Workbook

Sheet Dashboard
A1: Tracker — Jira Dashboard | L1: Metric | M1: Count
L2: Completed | M2: =D3 -> 206
A3: TOTAL ITEMS | B3: =COUNTIFS('_Data'!A$2:A$273,"Reflection Tree",'_Data'!D$2:D$273,"<>Epic",'_Data'!B$2:B$273,"<>")+COUNTIFS('_Data'!A$2:A$273,"Learning Path",'_Data'!D$2:D$273,"<>Epic",'_Data'!B$2:B$273,"<>")+COUNTIFS('_Data'!A$2:A$273,"System design",'_Data'!D$2:D$273,"<>Epic",'_Data'!B$2:B$273,"<>")+COUNTIFS('_Data'!A$2:A$273,"UX-UI",'_Data'!D$2:D$273,"<>Epic",'_Data'!B$2:B$273,"<>")+COUNTIFS('_Data'!A$2:A$273,"TEST",'_Data'!D$2:D$273,"<>Epic",'_Data'!B$2:B$273,"<>")+COUNTIFS('_Data'!A$2:A$273,"Authentication",'_Data'!D$2:D$273,"<>Epic",'_Data'!B$2:B$273,"<>")+COUNTIFS('_Data'!A$2:A$273,"Recommendation",'_Data'!D$2:D$273,"<>Epic",'_Data'!B$2:B$273,"<>")+COUNTIFS('_Data'!A$2:A$273,"Social Learning",'_Data'!D$2:D$273,"<>Epic",'_Data'!B$2:B$273,"<>")+COUNTIFS('_Data'!A$2:A$273,"Deploy",'_Data'!D$2:D$273,"<>Epic",'_Data'!B$2:B$273,"<>")+COUNTIFS('_Data'!A$2:A$273,"Dashboards",'_Data'!D$2:D$273,"<>Epic",'_Data'!B$2:B$273,"<>") -> 262 | C3: COMPLETED | D3: =COUNTIFS('_Data'!A$2:A$273,"Reflection Tree",'_Data'!E$2:E$273,"Done",'_Data'!D$2:D$273,"<>Epic",'_Data'!B$2:B$273,"<>")+COUNTIFS('_Data'!A$2:A$273,"Reflection Tree",'_Data'!E$2:E$273,"Closed",'_Data'!D$2:D$273,"<>Epic",'_Data'!B$2:B$273,"<>")+COUNTIFS('_Data'!A$2:A$273,"Reflection Tree",'_Data'!E$2:E$273,"Resolved",'_Data'!D$2:D$273,"<>Epic",'_Data'!B$2:B$273,"<>")+COUNTIFS('_Data'!A$2:A$273,"Learning Path",'_Data'!E$2:E$273,"Done",'_Data'!D$2:D$273,"<>Epic",'_Data'!B$2:B$273,"<>")+COUNTIFS('_Data'!A$2:A$273,"Learning Path",'_Data'!E$2:E$273,"Closed",'_Data'!D$2:D$273,"<>Epic",'_Data'!B$2:B$273,"<>")+COUNTIFS('_Data'!A$2:A$273,"Learning Path",'_Data'!E$2:E$273,"Resolved",'_Data'!D$2:D$273,"<>Epic",'_Data'!B$2:B$273,"<>")+COUNTIFS('_Data'!A$2:A$273,"System design",'_Data'!E$2:E$273,"Done",'_Data'!D$2:D$273,"<>Epic",'_Data'!B$2:B$273,"<>")+COUNTIFS('_Data'!A$2:A$273,"System design",'_Data'!E$2:E$273,"Closed",'_Data'!D$2:D$273,"<>Epic",'_Data'!B$2:B$273,"<>")+COUNTIFS('_Data'!A$2:A$273,"System design",'_Data'!E$2:E$273,"Resolved",'_Data'!D$2:D$273,"<>Epic",'_Data'!B$2:B$273,"<>")+COUNTIFS('_Data'!A$2:A$273,"UX-UI",'_Data'!E$2:E$273,"Done",'_Data'!D$2:D$273,"<>Epic",'_Data'!B$2:B$273,"<>")+COUNTIFS('_Data'!A$2:A$273,"UX-UI",'_Data'!E$2:E$273,"Closed",'_Data'!D$2:D$273,"<>Epic",'_Data'!B$2:B$273,"<>")+COUNTIFS('_Data'!A$2:A$273,"UX-UI",'_Data'!E$2:E$273,"Resolved",'_Data'!D$2:D$273,"<>Epic",'_Data'!B$2:B$273,"<>")+COUNTIFS('_Data'!A$2:A$273,"TEST",'_Data'!E$2:E$273,"Done",'_Data'!D$2:D$273,"<>Epic",'_Data'!B$2:B$273,"<>")+COUNTIFS('_Data'!A$2:A$273,"TEST",'_Data'!E$2:E$273,"Closed",'_Data'!D$2:D$273,"<>Epic",'_Data'!B$2:B$273,"<>")+COUNTIFS('_Data'!A$2:A$273,"TEST",'_Data'!E$2:E$273,"Resolved",'_Data'!D$2:D$273,"<>Epic",'_Data'!B$2:B$273,"<>")+COUNTIFS('_Data'!A$2:A$273,"Authentication",'_Data'!E$2:E$273,"Done",'_Data'!D$2:D$273,"<>Epic",'_Data'!B$2:B$273,"<>")+COUNTIFS('_Data'!A$2:A$273,"Authentication",'_Data'!E$2:E$273,"Closed",'_Data'!D$2:D$273,"<>Epic",'_Data'!B$2:B$273,"<>")+COUNTIFS('_Data'!A$2:A$273,"Authentication",'_Data'!E$2:E$273,"Resolved",'_Data'!D$2:D$273,"<>Epic",'_Data'!B$2:B$273,"<>")+COUNTIFS('_Data'!A$2:A$273,"Recommendation",'_Data'!E$2:E$273,"Done",'_Data'!D$2:D$273,"<>Epic",'_Data'!B$2:B$273,"<>")+COUNTIFS('_Data'!A$2:A$273,"Recommendation",'_Data'!E$2:E$273,"Closed",'_Data'!D$2:D$273,"<>Epic",'_Data'!B$2:B$273,"<>")+COUNTIFS('_Data'!A$2:A$273,"Recommendation",'_Data'!E$2:E$273,"Resolved",'_Data'!D$2:D$273,"<>Epic",'_Data'!B$2:B$273,"<>")+COUNTIFS('_Data'!A$2:A$273,"Social Learning",'_Data'!E$2:E$273,"Done",'_Data'!D$2:D$273,"<>Epic",'_Data'!B$2:B$273,"<>")+COUNTIFS('_Data'!A$2:A$273,"Social Learning",'_Data'!E$2:E$273,"Closed",'_Data'!D$2:D$273,"<>Epic",'_Data'!B$2:B$273,"<>")+COUNTIFS('_Data'!A$2:A$273,"Social Learning",'_Data'!E$2:E$273,"Resolved",'_Data'!D$2:D$273,"<>Epic",'_Data'!B$2:B$273,"<>")+COUNTIFS('_Data'!A$2:A$273,"Deploy",'_Data'!E$2:E$273,"Done",'_Data'!D$2:D$273,"<>Epic",'_Data'!B$2:B$273,"<>")+COUNTIFS('_Data'!A$2:A$273,"Deploy",'_Data'!E$2:E$273,"Closed",'_Data'!D$2:D$273,"<>Epic",'_Data'!B$2:B$273,"<>")+COUNTIFS('_Data'!A$2:A$273,"Deploy",'_Data'!E$2:E$273,"Resolved",'_Data'!D$2:D$273,"<>Epic",'_Data'!B$2:B$273,"<>")+COUNTIFS('_Data'!A$2:A$273,"Dashboards",'_Data'!E$2:E$273,"Done",'_Data'!D$2:D$273,"<>Epic",'_Data'!B$2:B$273,"<>")+COUNTIFS('_Data'!A$2:A$273,"Dashboards",'_Data'!E$2:E$273,"Closed",'_Data'!D$2:D$273,"<>Epic",'_Data'!B$2:B$273,"<>")+COUNTIFS('_Data'!A$2:A$273,"Dashboards",'_Data'!E$2:E$273,"Resolved",'_Data'!D$2:D$273,"<>Epic",'_Data'!B$2:B$273,"<>") -> 206 | E3: REMAINING | F3: =B3-D3 -> 56 | G3: PROGRESS | H3: =IFERROR(TEXT(D3/B3,"0.0%"),"0.0%") -> 78.6% | I3: LATEST SCRUM | J3: =IFERROR("SCRUM-"&TEXT(MAX('_Data'!C2:C267),"0"),"N/A") -> SCRUM-358 | L3: Remaining | M3: =F3 -> 56
A8: Epic Key | B8: Epic Name | C8: Epic Status | D8: Total Items | E8: Done | F8: Remaining | G8: Progress %
A9: SCRUM-3 | B9: Reflection Tree | C9: ='Reflection Tree'!D2 -> Done | D9: =COUNTIFS('_Data'!A$2:A$273,"Reflection Tree",'_Data'!D$2:D$273,"<>Epic",'_Data'!B$2:B$273,"<>") -> 19 | E9: =COUNTIFS('_Data'!A$2:A$273,"Reflection Tree",'_Data'!E$2:E$273,"Done",'_Data'!D$2:D$273,"<>Epic",'_Data'!B$2:B$273,"<>")+COUNTIFS('_Data'!A$2:A$273,"Reflection Tree",'_Data'!E$2:E$273,"Closed",'_Data'!D$2:D$273,"<>Epic",'_Data'!B$2:B$273,"<>")+COUNTIFS('_Data'!A$2:A$273,"Reflection Tree",'_Data'!E$2:E$273,"Resolved",'_Data'!D$2:D$273,"<>Epic",'_Data'!B$2:B$273,"<>") -> 19 | F9: =D9-E9 -> 0 | G9: =IFERROR(E9/D9,0) -> 1
A10: SCRUM-1 | B10: Learning Path | C10: ='Learning Path'!D2 -> Done | D10: =COUNTIFS('_Data'!A$2:A$273,"Learning Path",'_Data'!D$2:D$273,"<>Epic",'_Data'!B$2:B$273,"<>") -> 43 | E10: =COUNTIFS('_Data'!A$2:A$273,"Learning Path",'_Data'!E$2:E$273,"Done",'_Data'!D$2:D$273,"<>Epic",'_Data'!B$2:B$273,"<>")+COUNTIFS('_Data'!A$2:A$273,"Learning Path",'_Data'!E$2:E$273,"Closed",'_Data'!D$2:D$273,"<>Epic",'_Data'!B$2:B$273,"<>")+COUNTIFS('_Data'!A$2:A$273,"Learning Path",'_Data'!E$2:E$273,"Resolved",'_Data'!D$2:D$273,"<>Epic",'_Data'!B$2:B$273,"<>") -> 43 | F10: =D10-E10 -> 0 | G10: =IFERROR(E10/D10,0) -> 1
A11: SCRUM-8 | B11: System design | C11: ='System design'!D2 -> In Progress | D11: =COUNTIFS('_Data'!A$2:A$273,"System design",'_Data'!D$2:D$273,"<>Epic",'_Data'!B$2:B$273,"<>") -> 37 | E11: =COUNTIFS('_Data'!A$2:A$273,"System design",'_Data'!E$2:E$273,"Done",'_Data'!D$2:D$273,"<>Epic",'_Data'!B$2:B$273,"<>")+COUNTIFS('_Data'!A$2:A$273,"System design",'_Data'!E$2:E$273,"Closed",'_Data'!D$2:D$273,"<>Epic",'_Data'!B$2:B$273,"<>")+COUNTIFS('_Data'!A$2:A$273,"System design",'_Data'!E$2:E$273,"Resolved",'_Data'!D$2:D$273,"<>Epic",'_Data'!B$2:B$273,"<>") -> 32 | F11: =D11-E11 -> 5 | G11: =IFERROR(E11/D11,0) -> 0.86486486
A12: SCRUM-49 | B12: UX/UI | C12: ='UX-UI'!D2 -> In Progress | D12: =COUNTIFS('_Data'!A$2:A$273,"UX-UI",'_Data'!D$2:D$273,"<>Epic",'_Data'!B$2:B$273,"<>") -> 82 | E12: =COUNTIFS('_Data'!A$2:A$273,"UX-UI",'_Data'!E$2:E$273,"Done",'_Data'!D$2:D$273,"<>Epic",'_Data'!B$2:B$273,"<>")+COUNTIFS('_Data'!A$2:A$273,"UX-UI",'_Data'!E$2:E$273,"Closed",'_Data'!D$2:D$273,"<>Epic",'_Data'!B$2:B$273,"<>")+COUNTIFS('_Data'!A$2:A$273,"UX-UI",'_Data'!E$2:E$273,"Resolved",'_Data'!D$2:D$273,"<>Epic",'_Data'!B$2:B$273,"<>") -> 61 | F12: =D12-E12 -> 21 | G12: =IFERROR(E12/D12,0) -> 0.74390244
A13: SCRUM-30 | B13: TEST | C13: =TEST!D2 -> In Progress | D13: =COUNTIFS('_Data'!A$2:A$273,"TEST",'_Data'!D$2:D$273,"<>Epic",'_Data'!B$2:B$273,"<>") -> 14 | E13: =COUNTIFS('_Data'!A$2:A$273,"TEST",'_Data'!E$2:E$273,"Done",'_Data'!D$2:D$273,"<>Epic",'_Data'!B$2:B$273,"<>")+COUNTIFS('_Data'!A$2:A$273,"TEST",'_Data'!E$2:E$273,"Closed",'_Data'!D$2:D$273,"<>Epic",'_Data'!B$2:B$273,"<>")+COUNTIFS('_Data'!A$2:A$273,"TEST",'_Data'!E$2:E$273,"Resolved",'_Data'!D$2:D$273,"<>Epic",'_Data'!B$2:B$273,"<>") -> 6 | F13: =D13-E13 -> 8 | G13: =IFERROR(E13/D13,0) -> 0.42857143
A14: SCRUM-2 | B14: Authentication | C14: =Authentication!D2 -> In Progress | D14: =COUNTIFS('_Data'!A$2:A$273,"Authentication",'_Data'!D$2:D$273,"<>Epic",'_Data'!B$2:B$273,"<>") -> 26 | E14: =COUNTIFS('_Data'!A$2:A$273,"Authentication",'_Data'!E$2:E$273,"Done",'_Data'!D$2:D$273,"<>Epic",'_Data'!B$2:B$273,"<>")+COUNTIFS('_Data'!A$2:A$273,"Authentication",'_Data'!E$2:E$273,"Closed",'_Data'!D$2:D$273,"<>Epic",'_Data'!B$2:B$273,"<>")+COUNTIFS('_Data'!A$2:A$273,"Authentication",'_Data'!E$2:E$273,"Resolved",'_Data'!D$2:D$273,"<>Epic",'_Data'!B$2:B$273,"<>") -> 25 | F14: =D14-E14 -> 1 | G14: =IFERROR(E14/D14,0) -> 0.96153846
A15: SCRUM-6 | B15: Recommendation | C15: =Recommendation!D2 -> In Progress | D15: =COUNTIFS('_Data'!A$2:A$273,"Recommendation",'_Data'!D$2:D$273,"<>Epic",'_Data'!B$2:B$273,"<>") -> 16 | E15: =COUNTIFS('_Data'!A$2:A$273,"Recommendation",'_Data'!E$2:E$273,"Done",'_Data'!D$2:D$273,"<>Epic",'_Data'!B$2:B$273,"<>")+COUNTIFS('_Data'!A$2:A$273,"Recommendation",'_Data'!E$2:E$273,"Closed",'_Data'!D$2:D$273,"<>Epic",'_Data'!B$2:B$273,"<>")+COUNTIFS('_Data'!A$2:A$273,"Recommendation",'_Data'!E$2:E$273,"Resolved",'_Data'!D$2:D$273,"<>Epic",'_Data'!B$2:B$273,"<>") -> 4 | F15: =D15-E15 -> 12 | G15: =IFERROR(E15/D15,0) -> 0.25
A16: SCRUM-7 | B16: Social Learning | C16: ='Social Learning'!D2 -> Done | D16: =COUNTIFS('_Data'!A$2:A$273,"Social Learning",'_Data'!D$2:D$273,"<>Epic",'_Data'!B$2:B$273,"<>") -> 9 | E16: =COUNTIFS('_Data'!A$2:A$273,"Social Learning",'_Data'!E$2:E$273,"Done",'_Data'!D$2:D$273,"<>Epic",'_Data'!B$2:B$273,"<>")+COUNTIFS('_Data'!A$2:A$273,"Social Learning",'_Data'!E$2:E$273,"Closed",'_Data'!D$2:D$273,"<>Epic",'_Data'!B$2:B$273,"<>")+COUNTIFS('_Data'!A$2:A$273,"Social Learning",'_Data'!E$2:E$273,"Resolved",'_Data'!D$2:D$273,"<>Epic",'_Data'!B$2:B$273,"<>") -> 8 | F16: =D16-E16 -> 1 | G16: =IFERROR(E16/D16,0) -> 0.88888889
A17: SCRUM-58 | B17: Deploy | C17: =Deploy!D2 -> In Progress | D17: =COUNTIFS('_Data'!A$2:A$273,"Deploy",'_Data'!D$2:D$273,"<>Epic",'_Data'!B$2:B$273,"<>") -> 12 | E17: =COUNTIFS('_Data'!A$2:A$273,"Deploy",'_Data'!E$2:E$273,"Done",'_Data'!D$2:D$273,"<>Epic",'_Data'!B$2:B$273,"<>")+COUNTIFS('_Data'!A$2:A$273,"Deploy",'_Data'!E$2:E$273,"Closed",'_Data'!D$2:D$273,"<>Epic",'_Data'!B$2:B$273,"<>")+COUNTIFS('_Data'!A$2:A$273,"Deploy",'_Data'!E$2:E$273,"Resolved",'_Data'!D$2:D$273,"<>Epic",'_Data'!B$2:B$273,"<>") -> 8 | F17: =D17-E17 -> 4 | G17: =IFERROR(E17/D17,0) -> 0.66666667
A18: SCRUM-5 | B18: Dashboards | C18: =Dashboards!D2 -> To Do | D18: =COUNTIFS('_Data'!A$2:A$273,"Dashboards",'_Data'!D$2:D$273,"<>Epic",'_Data'!B$2:B$273,"<>") -> 4 | E18: =COUNTIFS('_Data'!A$2:A$273,"Dashboards",'_Data'!E$2:E$273,"Done",'_Data'!D$2:D$273,"<>Epic",'_Data'!B$2:B$273,"<>")+COUNTIFS('_Data'!A$2:A$273,"Dashboards",'_Data'!E$2:E$273,"Closed",'_Data'!D$2:D$273,"<>Epic",'_Data'!B$2:B$273,"<>")+COUNTIFS('_Data'!A$2:A$273,"Dashboards",'_Data'!E$2:E$273,"Resolved",'_Data'!D$2:D$273,"<>Epic",'_Data'!B$2:B$273,"<>") -> 0 | F18: =D18-E18 -> 4 | G18: =IFERROR(E18/D18,0) -> 0
A19: Sprint Timeline Summary
A20: Sprint | B20: Total Items | C20: Done | D20: Remaining | E20: Progress % | F20: Status
A21: SCRUM Sprint 1 | B21: 85 | C21: 85 | D21: 0 | E21: 100.0% | F21: Completed
A22: SCRUM Sprint 2 | B22: 46 | C22: 46 | D22: 0 | E22: 100.0% | F22: Completed
A23: SCRUM Sprint 3 | B23: 124 | C23: 75 | D23: 49 | E23: 60.5% | F23: In Progress
A24: SCRUM Sprint 4 | B24: 7 | C24: 0 | D24: 7 | E24: 0.0% | F24: Not Started
E27: 100.0% (85/85)
E28: 100.0% (46/46)
E29: 60.5% (75/124)
E30: 0.0% (0/7)

Sheet System design
A1: Issue key | B1: Summary | C1: Issue Type | D1: Status | E1: Priority | F1: Assignee | G1: Created | H1: Due date | I1: Story Points | J1: Sprint | K1: Parent Key | L1: Parent Summary
A2: SCRUM-8 | B2: System design | C2: Epic | D2: In Progress | E2: Highest | G2: 2025-11-17 | H2: 2026-03-16
A3: SCRUM-64 | B3: Infrastructure Set | C3: Task | D3: Done | E3: Medium | F3: Thiraphat Panthong | G3: 2025-12-16 | H3: 2025-12-29 | J3: SCRUM Sprint 1 | K3: SCRUM-8 | L3: System design
A4: SCRUM-72 | B4: AI-service Setup | C4: Subtask | D4: Done | E4: Medium | F4: Thiraphat Panthong | G4: 2025-12-17 | J4: SCRUM Sprint 1 | K4: SCRUM-64 | L4: Infrastructure Set
A5: SCRUM-71 | B5: Frontend Setup | C5: Subtask | D5: Done | E5: Medium | F5: Thiraphat Panthong | G5: 2025-12-17 | J5: SCRUM Sprint 1 | K5: SCRUM-64 | L5: Infrastructure Set
A6: SCRUM-70 | B6: Tech Stack Setup | C6: Subtask | D6: Done | E6: Medium | F6: Thiraphat Panthong | G6: 2025-12-17 | J6: SCRUM Sprint 1 | K6: SCRUM-64 | L6: Infrastructure Set
A7: SCRUM-69 | B7: Backend Setup | C7: Subtask | D7: Done | E7: Medium | F7: Thiraphat Panthong | G7: 2025-12-17 | J7: SCRUM Sprint 1 | K7: SCRUM-64 | L7: Infrastructure Set
A8: SCRUM-68 | B8: Set Docker Setup | C8: Subtask | D8: Done | E8: Medium | F8: Thiraphat Panthong | G8: 2025-12-17 | J8: SCRUM Sprint 1 | K8: SCRUM-64 | L8: Infrastructure Set
A9: SCRUM-45 | B9: Database Design | C9: Task | D9: Done | E9: Highest | F9: Nattapat Suwansipaisan | G9: 2025-11-17 | H9: 2025-12-29 | J9: SCRUM Sprint 1 | K9: SCRUM-8 | L9: System design
A10: SCRUM-195 | B10: Database table | C10: Subtask | D10: Done | E10: Medium | F10: Nattapat Suwansipaisan | G10: 2025-12-25 | H10: 2025-12-26 | J10: SCRUM Sprint 1 | K10: SCRUM-45 | L10: Database Design
A11: SCRUM-83 | B11: ER Diagram | C11: Subtask | D11: Done | E11: Medium | F11: Nattapat Suwansipaisan | G11: 2025-12-17 | H11: 2025-12-29 | J11: SCRUM Sprint 1 | K11: SCRUM-45 | L11: Database Design
A12: SCRUM-78 | B12: Connect to backend | C12: Subtask | D12: Done | E12: Medium | F12: Thiraphat Panthong | G12: 2025-12-17 | H12: 2025-12-30 | J12: SCRUM Sprint 1 | K12: SCRUM-45 | L12: Database Design
A13: SCRUM-80 | B13: Create Table | C13: Subtask | D13: Done | E13: Medium | F13: Nattapat Suwansipaisan | G13: 2025-12-17 | H13: 2025-12-29 | J13: SCRUM Sprint 1 | K13: SCRUM-45 | L13: Database Design
A14: SCRUM-89 | B14: Search System Template | C14: Task | D14: Done | E14: Medium | F14: Thiraphat Panthong | G14: 2025-12-17 | H14: 2026-01-02 | J14: SCRUM Sprint 1 | K14: SCRUM-8 | L14: System design
A15: SCRUM-211 | B15: Connect to Qdrant Database | C15: Subtask | D15: Done | E15: Medium | F15: Thiraphat Panthong | G15: 2025-12-29 | H15: 2025-12-29 | J15: SCRUM Sprint 1 | K15: SCRUM-89 | L15: Search System Template
A16: SCRUM-107 | B16: Ranking & Retrieval | C16: Subtask | D16: Done | E16: Medium | F16: Thiraphat Panthong | G16: 2025-12-17 | H16: 2025-12-29 | J16: SCRUM Sprint 1 | K16: SCRUM-89 | L16: Search System Template
A17: SCRUM-104 | B17: Tech Stack to use | C17: Subtask | D17: Done | E17: Medium | F17: Thiraphat Panthong | G17: 2025-12-17 | H17: 2025-12-29 | J17: SCRUM Sprint 1 | K17: SCRUM-89 | L17: Search System Template
A18: SCRUM-102 | B18: Preprocessing | C18: Subtask | D18: Done | E18: Medium | F18: Thiraphat Panthong | G18: 2025-12-17 | H18: 2025-12-29 | J18: SCRUM Sprint 1 | K18: SCRUM-89 | L18: Search System Template
A19: SCRUM-212 | B19: Embedding data | C19: Subtask | D19: Done | E19: Medium | F19: Thiraphat Panthong | G19: 2025-12-29 | H19: 2026-01-01 | J19: SCRUM Sprint 1 | K19: SCRUM-89 | L19: Search System Template
A20: SCRUM-108 | B20: Filtering | C20: Subtask | D20: Done | E20: Medium | F20: Thiraphat Panthong | G20: 2025-12-17 | H20: 2026-01-02 | J20: SCRUM Sprint 1 | K20: SCRUM-89 | L20: Search System Template
... A27: SCRUM-288 | B27: PoC for deploy | C27: Subtask | D27: Done | E27: Medium | F27: Thiraphat Panthong | G27: 2026-01-23 | H27: 2026-02-03 | J27: SCRUM Sprint 2 | K27: SCRUM-286 | L27: Integrate system (Deploy)
A28: SCRUM-46 | B28: API Design | C28: Task | D28: In Progress | E28: Highest | G28: 2025-11-17 | H28: 2026-03-16 | J28: SCRUM Sprint 3 | K28: SCRUM-8 | L28: System design
A29: SCRUM-202 | B29: Learning Path Node Endpoint | C29: Subtask | D29: Done | E29: Medium | F29: Napadech | G29: 2025-12-26 | H29: 2026-01-05 | J29: SCRUM Sprint 1 | K29: SCRUM-46 | L29: API Design
A30: SCRUM-201 | B30: Quiz Endpoint | C30: Subtask | D30: Done | E30: Medium | F30: Napadech | G30: 2025-12-25 | H30: 2026-01-05 | J30: SCRUM Sprint 2 | K30: SCRUM-46 | L30: API Design
A31: SCRUM-200 | B31: Tree Node Endpoint | C31: Subtask | D31: Done | E31: Medium | F31: Nattapat Suwansipaisan | G31: 2025-12-25 | H31: 2026-01-05 | J31: SCRUM Sprint 1 | K31: SCRUM-46 | L31: API Design
A32: SCRUM-199 | B32: Tree Endpoint | C32: Subtask | D32: Done | E32: Medium | F32: Nattapat Suwansipaisan | G32: 2025-12-25 | H32: 2026-01-05 | J32: SCRUM Sprint 1 | K32: SCRUM-46 | L32: API Design
A33: SCRUM-143 | B33: Recommendation Endpoints | C33: Subtask | D33: Done | E33: Medium | F33: Napadech | G33: 2025-12-18 | H33: 2026-01-30 | J33: SCRUM Sprint 2 | K33: SCRUM-46 | L33: API Design
A34: SCRUM-142 | B34: Lernnig path Endpoints | C34: Subtask | D34: Done | E34: Medium | F34: Napadech | G34: 2025-12-18 | H34: 2026-01-05 | J34: SCRUM Sprint 1 | K34: SCRUM-46 | L34: API Design
A35: SCRUM-141 | B35: Search Endpoints | C35: Subtask | D35: Done | E35: Medium | F35: Thiraphat Panthong | G35: 2025-12-18 | H35: 2026-01-05 | J35: SCRUM Sprint 1 | K35: SCRUM-46 | L35: API Design
A36: SCRUM-194 | B36: PROFILE Endpoint | C36: Subtask | D36: In Progress | E36: Medium | F36: Amy Tripp | G36: 2025-12-22 | H36: 2026-03-06 | J36: SCRUM Sprint 3 | K36: SCRUM-46 | L36: API Design
A37: SCRUM-140 | B37: Auth Endpoints | C37: Subtask | D37: In Progress | E37: Medium | F37: Nattapat Suwansipaisan | G37: 2025-12-18 | H37: 2026-01-28 | J37: SCRUM Sprint 2 | K37: SCRUM-46 | L37: API Design
A38: SCRUM-77 | B38: Document | C38: Subtask | D38: In Progress | E38: Medium | F38: Napadech | G38: 2025-12-17 | H38: 2026-03-16 | J38: SCRUM Sprint 3 | K38: SCRUM-46 | L38: API Design
A39: SCRUM-217 | B39: Dashboard Endpoint | C39: Subtask | D39: In Progress | E39: Medium | F39: Thiraphat Panthong | G39: 2026-01-04 | H39: 2026-03-06 | J39: SCRUM Sprint 3 | K39: SCRUM-46 | L39: API Design

Sheet UX-UI
A1: Issue key | B1: Summary | C1: Issue Type | D1: Status | E1: Priority | F1: Assignee | G1: Created | H1: Due date | I1: Story Points | J1: Sprint | K1: Parent Key | L1: Parent Summary
A2: SCRUM-49 | B2: UX/UI | C2: Epic | D2: In Progress | E2: Highest | G2: 2025-11-17 | H2: 2026-04-05
A3: SCRUM-181 | B3: Component-Widget | C3: Task | D3: Done | E3: Highest | F3: Nutgritta Prasomthongsuk | G3: 2025-12-20 | H3: 2026-01-04 | J3: SCRUM Sprint 1 | K3: SCRUM-49 | L3: UX/UI
A4: SCRUM-186 | B4: Components | C4: Subtask | D4: Done | E4: Medium | F4: Amy Tripp | G4: 2025-12-21 | J4: SCRUM Sprint 1 | K4: SCRUM-181 | L4: Component-Widget
A5: SCRUM-185 | B5: Buttons | C5: Subtask | D5: Done | E5: Medium | F5: Nutgritta Prasomthongsuk | G5: 2025-12-21 | J5: SCRUM Sprint 1 | K5: SCRUM-181 | L5: Component-Widget
A6: SCRUM-184 | B6: Theme And Color | C6: Subtask | D6: Done | E6: Medium | F6: Amy Tripp | G6: 2025-12-21 | J6: SCRUM Sprint 1 | K6: SCRUM-181 | L6: Component-Widget
A7: SCRUM-183 | B7: Typography | C7: Subtask | D7: Done | E7: Medium | F7: Nutgritta Prasomthongsuk | G7: 2025-12-21 | J7: SCRUM Sprint 1 | K7: SCRUM-181 | L7: Component-Widget
A8: SCRUM-51 | B8: Reflection Page Layout | C8: Task | D8: In Progress | E8: Highest | F8: Amy Tripp | G8: 2025-11-17 | H8: 2026-02-25 | J8: SCRUM Sprint 3 | K8: SCRUM-49 | L8: UX/UI
A9: SCRUM-81 | B9: Create New Tree Form | C9: Subtask | D9: Done | E9: High | F9: Amy Tripp | G9: 2025-12-17 | H9: 2026-01-27 | J9: SCRUM Sprint 3 | K9: SCRUM-51 | L9: Reflection Page Layout
A10: SCRUM-92 | B10: View Tree Information Page | C10: Subtask | D10: Done | E10: High | F10: Amy Tripp | G10: 2025-12-17 | H10: 2026-01-30 | J10: SCRUM Sprint 3 | K10: SCRUM-51 | L10: Reflection Page Layout
A11: SCRUM-87 | B11: Tree Visualization | C11: Subtask | D11: Done | E11: High | F11: Amy Tripp | G11: 2025-12-17 | H11: 2026-01-21 | J11: SCRUM Sprint 3 | K11: SCRUM-51 | L11: Reflection Page Layout
A12: SCRUM-84 | B12: Create Pop-Up | C12: Subtask | D12: Done | E12: High | F12: Amy Tripp | G12: 2025-12-17 | H12: 2026-01-27 | J12: SCRUM Sprint 3 | K12: SCRUM-51 | L12: Reflection Page Layout
A13: SCRUM-88 | B13: Change Album Info Pop-Up | C13: Subtask | D13: Done | E13: Medium | F13: Amy Tripp | G13: 2025-12-17 | H13: 2026-01-30 | J13: SCRUM Sprint 3 | K13: SCRUM-51 | L13: Reflection Page Layout
A14: SCRUM-94 | B14: Add Reflect Pop-Up | C14: Subtask | D14: Done | E14: Medium | F14: Amy Tripp | G14: 2025-12-17 | H14: 2026-01-30 | J14: SCRUM Sprint 3 | K14: SCRUM-51 | L14: Reflection Page Layout
A15: SCRUM-250 | B15: View Album Information Page | C15: Subtask | D15: Done | E15: Lowest | F15: Amy Tripp | G15: 2026-01-13 | H15: 2026-01-30 | J15: SCRUM Sprint 3 | K15: SCRUM-51 | L15: Reflection Page Layout
A16: SCRUM-86 | B16: How To Use Pop-Up | C16: Subtask | D16: Done | E16: Low | F16: Amy Tripp | G16: 2025-12-17 | H16: 2026-01-30 | J16: SCRUM Sprint 3 | K16: SCRUM-51 | L16: Reflection Page Layout
A17: SCRUM-85 | B17: Edit Pop-Up | C17: Subtask | D17: Done | E17: Medium | F17: Amy Tripp | G17: 2025-12-17 | H17: 2026-01-30 | J17: SCRUM Sprint 3 | K17: SCRUM-51 | L17: Reflection Page Layout
A18: SCRUM-95 | B18: Recommend Pop-Up | C18: Subtask | D18: Done | E18: Low | F18: Amy Tripp | G18: 2025-12-17 | H18: 2026-01-30 | J18: SCRUM Sprint 3 | K18: SCRUM-51 | L18: Reflection Page Layout
A19: SCRUM-96 | B19: Detail Pop-Up | C19: Subtask | D19: Done | E19: Low | F19: Amy Tripp | G19: 2025-12-17 | H19: 2026-01-30 | J19: SCRUM Sprint 3 | K19: SCRUM-51 | L19: Reflection Page Layout
... A23: SCRUM-293 | B23: Connect Backend URL | C23: Subtask | D23: Done | E23: Lowest | F23: Amy Tripp | G23: 2026-01-27 | H23: 2026-02-04 | J23: SCRUM Sprint 3 | K23: SCRUM-51 | L23: Reflection Page Layout
A24: SCRUM-346 | B24: Business Logic for CRUD | C24: Subtask | D24: Done | E24: High | F24: Amy Tripp | G24: 2026-02-18 | J24: SCRUM Sprint 3 | K24: SCRUM-51 | L24: Reflection Page Layout
A25: SCRUM-297 | B25: Change Location Popup | C25: Subtask | D25: Done | E25: Medium | F25: Amy Tripp | G25: 2026-01-28 | J25: SCRUM Sprint 3 | K25: SCRUM-51 | L25: Reflection Page Layout
A26: SCRUM-296 | B26: Delete Popup | C26: Subtask | D26: Done | E26: Low | F26: Amy Tripp | G26: 2026-01-28 | J26: SCRUM Sprint 3 | K26: SCRUM-51 | L26: Reflection Page Layout
A27: SCRUM-82 | B27: Page Layout | C27: Subtask | D27: Done | E27: Highest | F27: Amy Tripp | G27: 2025-12-17 | H27: 2025-12-31 | J27: SCRUM Sprint 3 | K27: SCRUM-51 | L27: Reflection Page Layout
A28: SCRUM-75 | B28: Component-Widget | C28: Subtask | D28: Done | E28: Highest | F28: Amy Tripp | G28: 2025-12-17 | H28: 2025-12-31 | J28: SCRUM Sprint 3 | K28: SCRUM-51 | L28: Reflection Page Layout
A29: SCRUM-347 | B29: Flow Optimization | C29: Subtask | D29: To Do | E29: Medium | F29: Amy Tripp | G29: 2026-02-18 | J29: SCRUM Sprint 3 | K29: SCRUM-51 | L29: Reflection Page Layout
A30: SCRUM-50 | B30: Learning Path Page Layout | C30: Task | D30: In Progress | E30: Highest | F30: Nutgritta Prasomthongsuk | G30: 2025-11-17 | H30: 2026-02-25 | J30: SCRUM Sprint 3 | K30: SCRUM-49 | L30: UX/UI
A31: SCRUM-74 | B31: Component-Widget | C31: Subtask | D31: Done | E31: Highest | F31: Nutgritta Prasomthongsuk | G31: 2025-12-17 | H31: 2026-01-09 | J31: SCRUM Sprint 3 | K31: SCRUM-50 | L31: Learning Path Page Layout
A32: SCRUM-155 | B32: [S]Learning Paths Overview Page | C32: Subtask | D32: Done | E32: Highest | F32: Nutgritta Prasomthongsuk | G32: 2025-12-18 | H32: 2026-01-06 | J32: SCRUM Sprint 3 | K32: SCRUM-50 | L32: Learning Path Page Layout
A33: SCRUM-168 | B33: [T]Create Status Page | C33: Subtask | D33: Done | E33: Highest | F33: Nutgritta Prasomthongsuk | G33: 2025-12-18 | H33: 2026-01-08 | J33: SCRUM Sprint 3 | K33: SCRUM-50 | L33: Learning Path Page Layout
A34: SCRUM-165 | B34: [T]Learning Path Status | C34: Subtask | D34: Done | E34: Medium | F34: Nutgritta Prasomthongsuk | G34: 2025-12-18 | H34: 2026-01-08 | J34: SCRUM Sprint 3 | K34: SCRUM-50 | L34: Learning Path Page Layout
A35: SCRUM-164 | B35: [T]Learning Paths Overview Page | C35: Subtask | D35: Done | E35: Highest | F35: Nutgritta Prasomthongsuk | G35: 2025-12-18 | H35: 2026-01-08 | J35: SCRUM Sprint 3 | K35: SCRUM-50 | L35: Learning Path Page Layout
A36: SCRUM-163 | B36: [T]Learn & Create Tab | C36: Subtask | D36: Done | E36: Medium | F36: Nutgritta Prasomthongsuk | G36: 2025-12-18 | H36: 2026-01-08 | J36: SCRUM Sprint 3 | K36: SCRUM-50 | L36: Learning Path Page Layout
A37: SCRUM-162 | B37: [S]Learning Path Status | C37: Subtask | D37: Done | E37: Highest | F37: Nutgritta Prasomthongsuk | G37: 2025-12-18 | H37: 2026-01-08 | J37: SCRUM Sprint 3 | K37: SCRUM-50 | L37: Learning Path Page Layout
A38: SCRUM-169 | B38: [T]Create Learning Path(Input Detail) | C38: Subtask | D38: Done | E38: Medium | F38: Nutgritta Prasomthongsuk | G38: 2025-12-18 | H38: 2026-01-11 | J38: SCRUM Sprint 3 | K38: SCRUM-50 | L38: Learning Path Page Layout
A39: SCRUM-175 | B39: [T]Create Node (Plain) | C39: Subtask | D39: Done | E39: Medium | F39: Nutgritta Prasomthongsuk | G39: 2025-12-18 | H39: 2026-01-28 | J39: SCRUM Sprint 3 | K39: SCRUM-50 | L39: Learning Path Page Layout
A40: SCRUM-174 | B40: [T]Create Plain Path | C40: Subtask | D40: Done | E40: Medium | F40: Nutgritta Prasomthongsuk | G40: 2025-12-18 | H40: 2026-01-28 | J40: SCRUM Sprint 3 | K40: SCRUM-50 | L40: Learning Path Page Layout
A41: SCRUM-172 | B41: [T]Create Node (AI) | C41: Subtask | D41: Done | E41: Medium | F41: Nutgritta Prasomthongsuk | G41: 2025-12-18 | H41: 2026-01-28 | J41: SCRUM Sprint 3 | K41: SCRUM-50 | L41: Learning Path Page Layout
... A52: SCRUM-158 | B52: [S]Quiz Page | C52: Subtask | D52: Done | E52: Medium | F52: Nutgritta Prasomthongsuk | G52: 2025-12-18 | H52: 2026-02-04 | J52: SCRUM Sprint 3 | K52: SCRUM-50 | L52: Learning Path Page Layout
A53: SCRUM-156 | B53: [S]Learning Page | C53: Subtask | D53: Done | E53: Highest | F53: Nutgritta Prasomthongsuk | G53: 2025-12-18 | J53: SCRUM Sprint 3 | K53: SCRUM-50 | L53: Learning Path Page Layout
...

Sheet Reflection Tree
A1: Issue key | B1: Summary | C1: Issue Type | D1: Status | E1: Priority | F1: Assignee | G1: Created | H1: Due date | I1: Story Points | J1: Sprint | K1: Parent Key | L1: Parent Summary
A2: SCRUM-3 | B2: Reflection Tree | C2: Epic | D2: Done | E2: Highest | G2: 2025-11-17 | H2: 2026-02-16
A3: SCRUM-191 | B3: Design Flow | C3: Task | D3: Done | E3: Highest | F3: Nattapat Suwansipaisan | G3: 2025-12-22 | H3: 2025-12-27 | J3: SCRUM Sprint 1 | K3: SCRUM-3 | L3: Reflection Tree
A4: SCRUM-13 | B4: Reflection Entry | C4: Task | D4: Done | E4: Highest | F4: Nattapat Suwansipaisan | G4: 2025-11-17 | H4: 2026-01-06 | J4: SCRUM Sprint 1 | K4: SCRUM-3 | L4: Reflection Tree
A5: SCRUM-226 | B5: Edit Reflection | C5: Subtask | D5: Done | E5: Medium | F5: Nattapat Suwansipaisan | G5: 2026-01-04 | H5: 2026-01-06 | J5: SCRUM Sprint 1 | K5: SCRUM-13 | L5: Reflection Entry
A6: SCRUM-225 | B6: Create Reflection | C6: Subtask | D6: Done | E6: Medium | F6: Nattapat Suwansipaisan | G6: 2026-01-04 | H6: 2026-01-06 | J6: SCRUM Sprint 1 | K6: SCRUM-13 | L6: Reflection Entry
A7: SCRUM-224 | B7: Delete Reflection | C7: Subtask | D7: Done | E7: Highest | F7: Nattapat Suwansipaisan | G7: 2026-01-04 | H7: 2026-01-06 | J7: SCRUM Sprint 1 | K7: SCRUM-13 | L7: Reflection Entry
A8: SCRUM-223 | B8: Read Reflection | C8: Subtask | D8: Done | E8: Highest | F8: Nattapat Suwansipaisan | G8: 2026-01-04 | H8: 2026-01-06 | J8: SCRUM Sprint 1 | K8: SCRUM-13 | L8: Reflection Entry
A9: SCRUM-221 | B9: Input/Output format | C9: Subtask | D9: Done | E9: Highest | F9: Nattapat Suwansipaisan | G9: 2026-01-04 | H9: 2026-01-06 | J9: SCRUM Sprint 1 | K9: SCRUM-13 | L9: Reflection Entry
A10: SCRUM-220 | B10: Collect reflection | C10: Subtask | D10: Done | E10: Highest | F10: Nattapat Suwansipaisan | G10: 2026-01-04 | H10: 2026-01-06 | J10: SCRUM Sprint 1 | K10: SCRUM-13 | L10: Reflection Entry
A11: SCRUM-15 | B11: AI Insight Analysis | C11: Task | D11: Done | E11: Highest | F11: Nattapat Suwansipaisan | G11: 2025-11-17 | H11: 2026-01-17 | J11: SCRUM Sprint 1 | K11: SCRUM-3 | L11: Reflection Tree
A12: SCRUM-230 | B12: Few-Shot Learning | C12: Subtask | D12: Done | E12: Highest | F12: Nattapat Suwansipaisan | G12: 2026-01-04 | H12: 2026-01-11 | J12: SCRUM Sprint 1 | K12: SCRUM-15 | L12: AI Insight Analysis
A13: SCRUM-227 | B13: Base Prompt Template | C13: Subtask | D13: Done | E13: Highest | F13: Nattapat Suwansipaisan | G13: 2026-01-04 | H13: 2026-01-11 | J13: SCRUM Sprint 1 | K13: SCRUM-15 | L13: AI Insight Analysis
A14: SCRUM-233 | B14: Re-ranking | C14: Subtask | D14: Done | E14: High | F14: Nattapat Suwansipaisan | G14: 2026-01-04 | H14: 2026-01-11 | J14: SCRUM Sprint 1 | K14: SCRUM-15 | L14: AI Insight Analysis
... A19: SCRUM-253 | B19: Reflection Album | C19: Task | D19: Done | E19: Medium | F19: Nattapat Suwansipaisan | G19: 2026-01-18 | H19: 2026-01-20 | J19: SCRUM Sprint 2 | K19: SCRUM-3 | L19: Reflection Tree
A20: SCRUM-360 | B20: Upload cover image | C20: Subtask | D20: Done | E20: Medium | F20: Nattapat Suwansipaisan | G20: 46085 | H20: 46090 | J20: SCRUM Sprint 3 | K20: SCRUM-253 | L20: Reflection Album
A21: SCRUM-238 | B21: Solve Bug | C21: Task | D21: Done | E21: Low | F21: Nattapat Suwansipaisan | G21: 2026-01-07 | H21: 2026-02-09 | J21: SCRUM Sprint 2 | K21: SCRUM-3 | L21: Reflection Tree
A22: SCRUM-361 | B22: Solve Bug & Optimize | C22: Task | D22: In Progress | E22: Low | F22: Nattapat Suwansipaisan | G22: 46085 | H22: 46090 | J22: SCRUM Sprint 3 | K22: SCRUM-3 | L22: Reflection Tree
A23: SCRUM-16 | B23: Link to Knowledge Tree, Tree Visualization | C23: Task | D23: Done | E23: Low | F23: Nattapat Suwansipaisan | G23: 2025-11-17 | H23: 2026-02-16 | J23: SCRUM Sprint 2 | K23: SCRUM-3 | L23: Reflection Tree

Sheet Learning Path
A1: Issue key | B1: Summary | C1: Issue Type | D1: Status | E1: Priority | F1: Assignee | G1: Created | H1: Due date | I1: Story Points | J1: Sprint | K1: Parent Key | L1: Parent Summary
A2: SCRUM-1 | B2: Learning Path | C2: Epic | D2: Done | E2: Highest | G2: 2025-11-17 | H2: 2026-02-16
A3: SCRUM-193 | B3: Design Flow | C3: Task | D3: Done | E3: Highest | F3: Thiraphat Panthong | G3: 2025-12-22 | H3: 2025-12-28 | J3: SCRUM Sprint 1 | K3: SCRUM-1 | L3: Learning Path
A4: SCRUM-189 | B4: Search Learning Path | C4: Task | D4: Done | E4: Medium | F4: Thiraphat Panthong | G4: 2025-12-22 | H4: 2026-01-18 | J4: SCRUM Sprint 1 | K4: SCRUM-1 | L4: Learning Path
A5: SCRUM-208 | B5: Search ranking | C5: Subtask | D5: Done | E5: Medium | F5: Thiraphat Panthong | G5: 2025-12-28 | H5: 2026-01-01 | J5: SCRUM Sprint 1 | K5: SCRUM-189 | L5: Search Learning Path
A6: SCRUM-204 | B6: Input/Output format | C6: Subtask | D6: Done | E6: Medium | F6: Thiraphat Panthong | G6: 2025-12-28 | H6: 2026-01-01 | J6: SCRUM Sprint 1 | K6: SCRUM-189 | L6: Search Learning Path
A7: SCRUM-203 | B7: Connect Qdrant (development) | C7: Subtask | D7: Done | E7: Medium | F7: Thiraphat Panthong | G7: 2025-12-28 | H7: 2026-01-01 | J7: SCRUM Sprint 1 | K7: SCRUM-189 | L7: Search Learning Path
A8: SCRUM-215 | B8: Use with real data | C8: Subtask | D8: Done | E8: Medium | F8: Thiraphat Panthong | G8: 2026-01-03 | H8: 2026-01-30 | J8: SCRUM Sprint 1 | K8: SCRUM-189 | L8: Search Learning Path
A9: SCRUM-207 | B9: Business logic | C9: Subtask | D9: Done | E9: Medium | F9: Thiraphat Panthong | G9: 2025-12-28 | H9: 2026-01-07 | J9: SCRUM Sprint 1 | K9: SCRUM-189 | L9: Search Learning Path
A10: SCRUM-206 | B10: Connect Qdrant (Production) | C10: Subtask | D10: Done | E10: Medium | F10: Thiraphat Panthong | G10: 2025-12-28 | H10: 2026-01-30 | J10: SCRUM Sprint 1 | K10: SCRUM-189 | L10: Search Learning Path
A11: SCRUM-205 | B11: Embedding with real data | C11: Subtask | D11: Done | E11: Medium | F11: Thiraphat Panthong | G11: 2025-12-28 | H11: 2026-01-30 | J11: SCRUM Sprint 1 | K11: SCRUM-189 | L11: Search Learning Path
A12: SCRUM-55 | B12: Collection Learning Path | C12: Task | D12: Done | E12: Highest | F12: Napadech | G12: 2025-11-17 | H12: 2026-01-06 | J12: SCRUM Sprint 1 | K12: SCRUM-1 | L12: Learning Path
A13: SCRUM-196 | B13: Read Learning Path | C13: Subtask | D13: Done | E13: Medium | F13: Napadech | G13: 2025-12-25 | J13: SCRUM Sprint 1 | K13: SCRUM-55 | L13: Collection Learning Path
A14: SCRUM-98 | B14: Delete Learning Path | C14: Subtask | D14: Done | E14: Medium | F14: Napadech | G14: 2025-12-17 | J14: SCRUM Sprint 1 | K14: SCRUM-55 | L14: Collection Learning Path
A15: SCRUM-93 | B15: Collect Learning Path | C15: Subtask | D15: Done | E15: Medium | F15: Napadech | G15: 2025-12-17 | J15: SCRUM Sprint 1 | K15: SCRUM-55 | L15: Collection Learning Path
A16: SCRUM-91 | B16: Edit Learning Path | C16: Subtask | D16: Done | E16: Medium | F16: Napadech | G16: 2025-12-17 | J16: SCRUM Sprint 1 | K16: SCRUM-55 | L16: Collection Learning Path
A17: SCRUM-90 | B17: Create Learning Path | C17: Subtask | D17: Done | E17: Medium | F17: Napadech | G17: 2025-12-17 | J17: SCRUM Sprint 1 | K17: SCRUM-55 | L17: Collection Learning Path
A18: SCRUM-9 | B18: Path Generator | C18: Task | D18: Done | E18: Highest | F18: Napadech | G18: 2025-11-17 | H18: 2026-01-13 | J18: SCRUM Sprint 1 | K18: SCRUM-1 | L18: Learning Path
A19: SCRUM-100 | B19: Plain Path | C19: Subtask | D19: Done | E19: Medium | F19: Napadech | G19: 2025-12-17 | H19: 2026-01-10 | J19: SCRUM Sprint 1 | K19: SCRUM-9 | L19: Path Generator
A20: SCRUM-99 | B20: Example data | C20: Subtask | D20: Done | E20: Medium | F20: Napadech | G20: 2025-12-17 | H20: 2026-01-10 | J20: SCRUM Sprint 1 | K20: SCRUM-9 | L20: Path Generator
A21: SCRUM-248 | B21: Send to GO | C21: Subtask | D21: Done | E21: Medium | F21: Napadech | G21: 2026-01-08 | H21: 2026-01-14 | J21: SCRUM Sprint 1 | K21: SCRUM-9 | L21: Path Generator
A22: SCRUM-247 | B22: LLM Output -> Schema | C22: Subtask | D22: Done | E22: Medium | F22: Napadech | G22: 2026-01-08 | H22: 2026-01-13 | J22: SCRUM Sprint 1 | K22: SCRUM-9 | L22: Path Generator
A23: SCRUM-245 | B23: LLM Result Parser & Validator | C23: Subtask | D23: Done | E23: Medium | F23: Napadech | G23: 2026-01-08 | H23: 2026-01-13 | J23: SCRUM Sprint 1 | K23: SCRUM-9 | L23: Path Generator
A24: SCRUM-244 | B24: Exception Handling & Retry Logic | C24: Subtask | D24: Done | E24: Medium | F24: Napadech | G24: 2026-01-08 | H24: 2026-01-13 | J24: SCRUM Sprint 1 | K24: SCRUM-9 | L24: Path Generator
A25: SCRUM-243 | B25: Similarity & Re-ranking | C25: Subtask | D25: Done | E25: Medium | F25: Napadech | G25: 2026-01-08 | H25: 2026-01-10 | J25: SCRUM Sprint 1 | K25: SCRUM-9 | L25: Path Generator
A26: SCRUM-242 | B26: Base Prompt Template | C26: Subtask | D26: Done | E26: Medium | F26: Napadech | G26: 2026-01-08 | H26: 2026-01-10 | J26: SCRUM Sprint 1 | K26: SCRUM-9 | L26: Path Generator
A27: SCRUM-239 | B27: Sample data | C27: Task | D27: Done | E27: Medium | F27: Thiraphat Panthong | G27: 2026-01-07 | H27: 2026-01-20 | J27: SCRUM Sprint 1 | K27: SCRUM-1 | L27: Learning Path
A28: SCRUM-240 | B28: Cover learning path | C28: Subtask | D28: Done | E28: Medium | F28: Thiraphat Panthong | G28: 2026-01-07 | J28: SCRUM Sprint 1 | K28: SCRUM-239 | L28: Sample data
A29: SCRUM-252 | B29: Load into DB | C29: Subtask | D29: Done | E29: Medium | F29: Thiraphat Panthong | G29: 2026-01-15 | J29: SCRUM Sprint 1 | K29: SCRUM-239 | L29: Sample data
A30: SCRUM-251 | B30: Data JSON format | C30: Subtask | D30: Done | E30: Medium | F30: Thiraphat Panthong | G30: 2026-01-14 | J30: SCRUM Sprint 1 | K30: SCRUM-239 | L30: Sample data
A31: SCRUM-115 | B31: History System | C31: Task | D31: Done | E31: Medium | F31: Napadech | G31: 2025-12-17 | H31: 2026-01-19 | J31: SCRUM Sprint 1 | K31: SCRUM-1 | L31: Learning Path
A32: SCRUM-118 | B32: Assessment & Performance | C32: Subtask | D32: Done | E32: Medium | F32: Napadech | G32: 2025-12-17 | H32: 2026-01-14 | J32: SCRUM Sprint 1 | K32: SCRUM-115 | L32: History System
A33: SCRUM-117 | B33: Progression History | C33: Subtask | D33: Done | E33: Medium | F33: Napadech | G33: 2025-12-17 | H33: 2026-01-14 | J33: SCRUM Sprint 1 | K33: SCRUM-115 | L33: History System
A34: SCRUM-116 | B34: Activity & Event | C34: Subtask | D34: Done | E34: Medium | F34: Napadech | G34: 2025-12-17 | H34: 2026-01-14 | J34: SCRUM Sprint 1 | K34: SCRUM-115 | L34: History System
A35: SCRUM-10 | B35: Progress Visualization | C35: Task | D35: Done | E35: Medium | F35: Napadech | G35: 2025-11-17 | H35: 2026-01-19 | J35: SCRUM Sprint 1 | K35: SCRUM-1 | L35: Learning Path
A36: SCRUM-123 | B36: State Persistence | C36: Subtask | D36: Done | E36: Medium | F36: Napadech | G36: 2025-12-17 | H36: 2026-01-19 | J36: SCRUM Sprint 1 | K36: SCRUM-10 | L36: Progress Visualization
A37: SCRUM-122 | B37: Real-time Calculation Engine | C37: Subtask | D37: Done | E37: Medium | F37: Napadech | G37: 2025-12-17 | H37: 2026-01-19 | J37: SCRUM Sprint 1 | K37: SCRUM-10 | L37: Progress Visualization
A38: SCRUM-121 | B38: Status Indicators | C38: Subtask | D38: Done | E38: Medium | F38: Napadech | G38: 2025-12-17 | H38: 2026-01-19 | J38: SCRUM Sprint 1 | K38: SCRUM-10 | L38: Progress Visualization
A39: SCRUM-120 | B39: Time Remaining Estimate | C39: Subtask | D39: Done | E39: Medium | F39: Napadech | G39: 2025-12-17 | H39: 2026-01-19 | J39: SCRUM Sprint 1 | K39: SCRUM-10 | L39: Progress Visualization
A40: SCRUM-119 | B40: Progress Bar (Percentage) | C40: Subtask | D40: Done | E40: Medium | F40: Napadech | G40: 2025-12-17 | H40: 2026-01-19 | J40: SCRUM Sprint 1 | K40: SCRUM-10 | L40: Progress Visualization
...

Sheet Authentication
A1: Issue key | B1: Summary | C1: Issue Type | D1: Status | E1: Priority | F1: Assignee | G1: Created | H1: Due date | I1: Story Points | J1: Sprint | K1: Parent Key | L1: Parent Summary
A2: SCRUM-2 | B2: Authentication | C2: Epic | D2: In Progress | E2: High | G2: 2025-11-17 | H2: 2026-02-27
A3: SCRUM-249 | B3: CRUD | C3: Task | D3: Done | E3: Highest | F3: Thiraphat Panthong | G3: 2026-01-12 | H3: 2026-01-13 | J3: SCRUM Sprint 1 | K3: SCRUM-2 | L3: Authentication
A4: SCRUM-17 | B4: User Account & Identity Model | C4: Task | D4: Done | E4: Highest | F4: Thiraphat Panthong | G4: 2025-11-17 | H4: 2026-01-13 | J4: SCRUM Sprint 2 | K4: SCRUM-2 | L4: Authentication
A5: SCRUM-126 | B5: Refresh Token Logic | C5: Task | D5: Done | E5: Medium | F5: Thiraphat Panthong | G5: 2025-12-18 | H5: 2026-01-15 | J5: SCRUM Sprint 2 | K5: SCRUM-2 | L5: Authentication
A6: SCRUM-19 | B6: Login & Signup Logic | C6: Task | D6: Done | E6: High | F6: Thiraphat Panthong | G6: 2025-11-17 | H6: 2026-01-15 | J6: SCRUM Sprint 2 | K6: SCRUM-2 | L6: Authentication
A7: SCRUM-130 | B7: Password management | C7: Task | D7: Done | E7: High | F7: Thiraphat Panthong | G7: 2025-12-18 | H7: 2026-01-23 | J7: SCRUM Sprint 2 | K7: SCRUM-2 | L7: Authentication
A8: SCRUM-129 | B8: Forgot Password Workflow | C8: Task | D8: Done | E8: Highest | F8: Thiraphat Panthong | G8: 2025-12-18 | H8: 2026-01-23 | J8: SCRUM Sprint 2 | K8: SCRUM-2 | L8: Authentication
A9: SCRUM-18 | B9: Email Verification | C9: Task | D9: Done | E9: Highest | F9: Thiraphat Panthong | G9: 2025-11-17 | H9: 2026-01-23 | J9: SCRUM Sprint 2 | K9: SCRUM-2 | L9: Authentication
A10: SCRUM-132 | B10: Role-Based Access Control | C10: Task | D10: Done | E10: High | F10: Thiraphat Panthong | G10: 2025-12-18 | H10: 2026-02-15 | J10: SCRUM Sprint 2 | K10: SCRUM-2 | L10: Authentication
A11: SCRUM-131 | B11: Login Rate Limiting | C11: Task | D11: Done | E11: Medium | F11: Thiraphat Panthong | G11: 2025-12-18 | H11: 2026-02-15 | J11: SCRUM Sprint 2 | K11: SCRUM-2 | L11: Authentication
A12: SCRUM-269 | B12: Session & Token Management | C12: Task | D12: Done | E12: High | F12: Nattapat Suwansipaisan | G12: 2026-01-23 | H12: 2026-02-17 | J12: SCRUM Sprint 2 | K12: SCRUM-2 | L12: Authentication
A13: SCRUM-275 | B13: Multi-device Session Control | C13: Subtask | D13: Done | E13: Medium | F13: Nattapat Suwansipaisan | G13: 2026-01-23 | H13: 2026-02-12 | J13: SCRUM Sprint 2 | K13: SCRUM-269 | L13: Session & Token Management
A14: SCRUM-274 | B14: Refresh Token Logic | C14: Subtask | D14: Done | E14: Medium | F14: Nattapat Suwansipaisan | G14: 2026-01-23 | H14: 2026-02-16 | J14: SCRUM Sprint 2 | K14: SCRUM-269 | L14: Session & Token Management
... A27: SCRUM-325 | B27: Authentication | C27: Subtask | D27: Done | E27: Medium | F27: Thiraphat Panthong | G27: 2026-02-13 | H27: 2026-02-16 | J27: SCRUM Sprint 2 | K27: SCRUM-133 | L27: Protected Routes
A28: SCRUM-310 | B28: Admin | C28: Task | D28: To Do | E28: Medium | F28: Thiraphat Panthong | G28: 2026-02-07 | H28: 46087 | J28: SCRUM Sprint 3 | K28: SCRUM-2 | L28: Authentication

Sheet Recommendation
A1: Issue key | B1: Summary | C1: Issue Type | D1: Status | E1: Priority | F1: Assignee | G1: Created | H1: Due date | I1: Story Points | J1: Sprint | K1: Parent Key | L1: Parent Summary
A2: SCRUM-6 | B2: Recommendation | C2: Epic | D2: In Progress | E2: High | F2: Napadech | G2: 2025-11-17 | H2: 2026-03-10
A3: SCRUM-37 | B3: Data Pipeline | C3: Task | D3: In Progress | E3: Medium | F3: Napadech | G3: 2025-11-17 | H3: 2026-03-10 | J3: SCRUM Sprint 3 | K3: SCRUM-6 | L3: Recommendation
A4: SCRUM-313 | B4: Design Flow (learning path) | C4: Subtask | D4: Done | E4: Highest | F4: Napadech | G4: 2026-02-09 | H4: 2026-02-09 | J4: SCRUM Sprint 3 | K4: SCRUM-37 | L4: Data Pipeline
A5: SCRUM-301 | B5: Define Data Model | C5: Subtask | D5: Done | E5: High | F5: Napadech | G5: 2026-02-06 | H5: 2026-02-11 | J5: SCRUM Sprint 3 | K5: SCRUM-37 | L5: Data Pipeline
A6: SCRUM-259 | B6: User Assessment Design | C6: Subtask | D6: Done | E6: Highest | F6: Napadech | G6: 2026-01-21 | H6: 2026-02-11 | J6: SCRUM Sprint 3 | K6: SCRUM-37 | L6: Data Pipeline
A7: SCRUM-282 | B7: Define Algorithm | C7: Subtask | D7: Done | E7: High | F7: Napadech | G7: 2026-01-23 | H7: 2026-02-11 | J7: SCRUM Sprint 3 | K7: SCRUM-37 | L7: Data Pipeline
A8: SCRUM-262 | B8: Strategy for New Users | C8: Subtask | D8: To Do | E8: Highest | F8: Napadech | G8: 2026-01-21 | H8: 2026-02-11 | J8: SCRUM Sprint 3 | K8: SCRUM-37 | L8: Data Pipeline
A9: SCRUM-281 | B9: Feedback Loop Integration | C9: Subtask | D9: To Do | E9: Medium | F9: Napadech | G9: 2026-01-23 | H9: 2026-02-27 | J9: SCRUM Sprint 3 | K9: SCRUM-37 | L9: Data Pipeline
A10: SCRUM-280 | B10: Strategy for Improve Model | C10: Subtask | D10: To Do | E10: Medium | F10: Napadech | G10: 2026-01-23 | H10: 2026-02-27 | J10: SCRUM Sprint 3 | K10: SCRUM-37 | L10: Data Pipeline
A11: SCRUM-279 | B11: Storage to use | C11: Subtask | D11: To Do | E11: High | F11: Napadech | G11: 2026-01-23 | H11: 2026-02-13 | J11: SCRUM Sprint 3 | K11: SCRUM-37 | L11: Data Pipeline
A12: SCRUM-277 | B12: Orchestrator | C12: Subtask | D12: To Do | E12: High | F12: Napadech | G12: 2026-01-23 | H12: 2026-02-13 | J12: SCRUM Sprint 3 | K12: SCRUM-37 | L12: Data Pipeline
A13: SCRUM-260 | B13: Implement Interest Tagging | C13: Subtask | D13: To Do | E13: Highest | F13: Napadech | G13: 2026-01-21 | H13: 2026-02-11 | J13: SCRUM Sprint 3 | K13: SCRUM-37 | L13: Data Pipeline
A14: SCRUM-314 | B14: implement full-pipeline | C14: Subtask | D14: To Do | E14: Medium | F14: Napadech | G14: 2026-02-09 | H14: 2026-02-27 | J14: SCRUM Sprint 3 | K14: SCRUM-37 | L14: Data Pipeline
... A18: SCRUM-351 | B18: Integration to Learning Path | C18: Task | D18: To Do | E18: Medium | F18: Napadech | G18: 2026-02-19 | H18: 2026-03-10 | J18: SCRUM Sprint 3 | K18: SCRUM-6 | L18: Recommendation

Sheet Social Learning
A1: Issue key | B1: Summary | C1: Issue Type | D1: Status | E1: Priority | F1: Assignee | G1: Created | H1: Due date | I1: Story Points | J1: Sprint | K1: Parent Key | L1: Parent Summary
A2: SCRUM-7 | B2: Social Learning | C2: Epic | D2: Done | E2: Medium | G2: 2025-11-17 | H2: 2026-03-06
A3: SCRUM-43 | B3: Comment Display UI | C3: Task | D3: Done | E3: Medium | F3: Thiraphat Panthong | G3: 2025-11-17 | H3: 2026-02-25 | J3: SCRUM Sprint 3 | K3: SCRUM-7 | L3: Social Learning
A4: SCRUM-42 | B4: Comment Creation | C4: Task | D4: Done | E4: Medium | F4: Nattapat Suwansipaisan | G4: 2025-11-17 | H4: 2026-03-02 | J4: SCRUM Sprint 3 | K4: SCRUM-7 | L4: Social Learning
A5: SCRUM-354 | B5: Comment Reply | C5: Task | D5: Done | E5: Medium | F5: Nattapat Suwansipaisan | H5: 46085 | J5: SCRUM Sprint 3 | K5: SCRUM-7 | L5: Social Learning
A6: SCRUM-355 | B6: Mention base on username | C6: Subtask | D6: Done | E6: Medium | F6: Nattapat Suwansipaisan | H6: 46085 | J6: SCRUM Sprint 3 | K6: SCRUM-354 | L6: =IFERROR(INDEX($B$2:$B$1000,MATCH(K6,$A$2:$A$1000,0)),"") -> Comment Reply
A7: SCRUM-356 | B7: Mention base Display Full name | C7: Subtask | D7: Done | E7: Medium | F7: Thiraphat Panthong | H7: 46085 | J7: SCRUM Sprint 3 | K7: SCRUM-354 | L7: =IFERROR(INDEX($B$2:$B$1000,MATCH(K7,$A$2:$A$1000,0)),"") -> Comment Reply
A8: SCRUM-353 | B8: Comment Reaction | C8: Task | D8: Done | E8: Medium | F8: Thiraphat Panthong | H8: 46085 | J8: SCRUM Sprint 3 | K8: SCRUM-7 | L8: =IFERROR(INDEX($B$2:$B$1000,MATCH(K8,$A$2:$A$1000,0)),"") -> Social Learning
A9: SCRUM-357 | B9: Count reaction | C9: Subtask | D9: Done | E9: Medium | F9: Thiraphat Panthong | H9: 46085 | J9: SCRUM Sprint 3 | K9: SCRUM-353 | L9: =IFERROR(INDEX($B$2:$B$1000,MATCH(K9,$A$2:$A$1000,0)),"") -> Comment Reaction
A10: SCRUM-358 | B10: One person for count one action | C10: Subtask | D10: Done | E10: Medium | F10: Thiraphat Panthong | H10: 46085 | J10: SCRUM Sprint 3 | K10: SCRUM-353 | L10: =IFERROR(INDEX($B$2:$B$1000,MATCH(K10,$A$2:$A$1000,0)),"") -> Comment Reaction
A11: SCRUM-44 | B11: Edit & Delete Comment | C11: Task | D11: To Do | E11: Medium | F11: Thiraphat Panthong | G11: 2025-11-17 | H11: 46087 | J11: SCRUM Sprint 3 | K11: SCRUM-7 | L11: Social Learning
D12: =IF(A12<>"","To Do","") | L12: =IF(K12<>"",IFERROR(INDEX($B$2:$B$1000,MATCH(K12,$A$2:$A$1000,0)),""),"")
D13: =IF(A13<>"","To Do","") | L13: =IF(K13<>"",IFERROR(INDEX($B$2:$B$1000,MATCH(K13,$A$2:$A$1000,0)),""),"")
D14: =IF(A14<>"","To Do","") | L14: =IF(K14<>"",IFERROR(INDEX($B$2:$B$1000,MATCH(K14,$A$2:$A$1000,0)),""),"")
D15: =IF(A15<>"","To Do","") | L15: =IF(K15<>"",IFERROR(INDEX($B$2:$B$1000,MATCH(K15,$A$2:$A$1000,0)),""),"")
D16: =IF(A16<>"","To Do","") | L16: =IF(K16<>"",IFERROR(INDEX($B$2:$B$1000,MATCH(K16,$A$2:$A$1000,0)),""),"")
D17: =IF(A17<>"","To Do","") | L17: =IF(K17<>"",IFERROR(INDEX($B$2:$B$1000,MATCH(K17,$A$2:$A$1000,0)),""),"")
D18: =IF(A18<>"","To Do","") | L18: =IF(K18<>"",IFERROR(INDEX($B$2:$B$1000,MATCH(K18,$A$2:$A$1000,0)),""),"")
D19: =IF(A19<>"","To Do","") | L19: =IF(K19<>"",IFERROR(INDEX($B$2:$B$1000,MATCH(K19,$A$2:$A$1000,0)),""),"")
D20: =IF(A20<>"","To Do","") | L20: =IF(K20<>"",IFERROR(INDEX($B$2:$B$1000,MATCH(K20,$A$2:$A$1000,0)),""),"")
D21: =IF(A21<>"","To Do","") | L21: =IF(K21<>"",IFERROR(INDEX($B$2:$B$1000,MATCH(K21,$A$2:$A$1000,0)),""),"")
D22: =IF(A22<>"","To Do","") | L22: =IF(K22<>"",IFERROR(INDEX($B$2:$B$1000,MATCH(K22,$A$2:$A$1000,0)),""),"")
D23: =IF(A23<>"","To Do","") | L23: =IF(K23<>"",IFERROR(INDEX($B$2:$B$1000,MATCH(K23,$A$2:$A$1000,0)),""),"")
... D61: =IF(A61<>"","To Do","") | L61: =IF(K61<>"",IFERROR(INDEX($B$2:$B$1000,MATCH(K61,$A$2:$A$1000,0)),""),"")

Sheet Dashboards
A1: Issue key | B1: Summary | C1: Issue Type | D1: Status | E1: Priority | F1: Assignee | G1: Created | H1: Due date | I1: Story Points | J1: Sprint | K1: Parent Key | L1: Parent Summary
A2: SCRUM-5 | B2: Dashboards | C2: Epic | D2: To Do | E2: Medium | G2: 2025-11-17 | H2: 2026-03-27
A3: SCRUM-28 | B3: Student/Teacher Dashboard | C3: Task | D3: To Do | E3: Medium | F3: Amy Tripp | G3: 2025-11-17 | H3: 2026-03-11 | J3: SCRUM Sprint 3 | K3: SCRUM-5 | L3: Dashboards
A4: SCRUM-29 | B4: Progress Visualization | C4: Task | D4: To Do | E4: Medium | F4: Amy Tripp | G4: 2025-11-17 | H4: 2026-03-17 | J4: SCRUM Sprint 3 | K4: SCRUM-5 | L4: Dashboards
A5: SCRUM-31 | B5: Admin Overview Dashboard | C5: Task | D5: To Do | E5: Medium | F5: Amy Tripp | G5: 2025-11-17 | H5: 2026-03-22 | J5: SCRUM Sprint 3 | K5: SCRUM-5 | L5: Dashboards
A6: SCRUM-32 | B6: Data Export | C6: Task | D6: To Do | E6: Medium | F6: Amy Tripp | G6: 2025-11-17 | H6: 2026-03-27 | J6: SCRUM Sprint 3 | K6: SCRUM-5 | L6: Dashboards

Sheet TEST
A1: Issue key | B1: Summary | C1: Issue Type | D1: Status | E1: Priority | F1: Assignee | G1: Created | H1: Due date | I1: Story Points | J1: Sprint | K1: Parent Key | L1: Parent Summary
A2: SCRUM-30 | B2: TEST | C2: Epic | D2: In Progress | E2: Medium | F2: Nattapat Suwansipaisan | G2: 2025-11-17 | H2: 2026-04-17
A3: SCRUM-35 | B3: Sprint 1 Testing | C3: Test | D3: Done | E3: Highest | F3: Nattapat Suwansipaisan | G3: 2025-11-17 | H3: 2026-01-21 | J3: SCRUM Sprint 1 | K3: SCRUM-30 | L3: TEST
A4: SCRUM-219 | B4: Test design | C4: Subtask | D4: Done | E4: Medium | F4: Nattapat Suwansipaisan | G4: 2026-01-04 | H4: 2026-01-19 | J4: SCRUM Sprint 1 | K4: SCRUM-35 | L4: Sprint 1 Testing
A5: SCRUM-33 | B5: Sprint 2 Testing | C5: Test | D5: Done | E5: High | F5: Nattapat Suwansipaisan | G5: 2025-11-17 | H5: 2026-02-19 | J5: SCRUM Sprint 2 | K5: SCRUM-30 | L5: TEST
A6: SCRUM-234 | B6: Test design | C6: Subtask | D6: Done | E6: Medium | F6: Nattapat Suwansipaisan | G6: 2026-01-05 | H6: 2026-02-16 | J6: SCRUM Sprint 2 | K6: SCRUM-33 | L6: Sprint 2 Testing
A7: SCRUM-150 | B7: API Testing | C7: Subtask | D7: Done | E7: Medium | F7: Nattapat Suwansipaisan | G7: 2025-12-18 | H7: 2026-02-19 | J7: SCRUM Sprint 2 | K7: SCRUM-33 | L7: Sprint 2 Testing
A8: SCRUM-149 | B8: Integration Testing | C8: Subtask | D8: Done | E8: Medium | F8: Nattapat Suwansipaisan | G8: 2025-12-18 | H8: 2026-02-19 | J8: SCRUM Sprint 2 | K8: SCRUM-33 | L8: Sprint 2 Testing
A9: SCRUM-34 | B9: Sprint 3 Testing | C9: Test | D9: To Do | E9: Low | F9: Nattapat Suwansipaisan | G9: 2025-11-17 | H9: 2026-03-16 | J9: SCRUM Sprint 3 | K9: SCRUM-30 | L9: TEST
A10: SCRUM-235 | B10: Test design | C10: Subtask | D10: To Do | E10: Medium | F10: Nattapat Suwansipaisan | G10: 2026-01-05 | J10: SCRUM Sprint 3 | K10: SCRUM-34 | L10: Sprint 3 Testing
A11: SCRUM-153 | B11: API Testing | C11: Subtask | D11: To Do | E11: Medium | G11: 2025-12-18 | J11: SCRUM Sprint 3 | K11: SCRUM-34 | L11: Sprint 3 Testing
A12: SCRUM-152 | B12: Integration Testing | C12: Subtask | D12: To Do | E12: Medium | G12: 2025-12-18 | J12: SCRUM Sprint 3 | K12: SCRUM-34 | L12: Sprint 3 Testing
A13: SCRUM-151 | B13: Unit Testing | C13: Subtask | D13: To Do | E13: Medium | G13: 2025-12-18 | J13: SCRUM Sprint 3 | K13: SCRUM-34 | L13: Sprint 3 Testing
A14: SCRUM-36 | B14: Sprint 4 Testing | C14: Test | D14: To Do | E14: Lowest | F14: Nattapat Suwansipaisan | G14: 2025-11-17 | H14: 2026-04-17 | J14: SCRUM Sprint 4 | K14: SCRUM-30 | L14: TEST
A15: SCRUM-236 | B15: Test design | C15: Subtask | D15: To Do | E15: Medium | F15: Nattapat Suwansipaisan | G15: 2026-01-05 | J15: SCRUM Sprint 4 | K15: SCRUM-36 | L15: Sprint 4 Testing
A16: SCRUM-147 | B16: End-to-End (E2E) Testing | C16: Subtask | D16: To Do | E16: Medium | G16: 2025-12-18 | J16: SCRUM Sprint 4 | K16: SCRUM-36 | L16: Sprint 4 Testing

Sheet Deploy
A1: Issue key | B1: Summary | C1: Issue Type | D1: Status | E1: Priority | F1: Assignee | G1: Created | H1: Due date | I1: Story Points | J1: Sprint | K1: Parent Key | L1: Parent Summary
A2: SCRUM-58 | B2: Deploy | C2: Epic | D2: In Progress | E2: Medium | F2: Thiraphat Panthong | G2: 2025-11-19 | H2: 2026-04-17
A3: SCRUM-317 | B3: PoC with CI/CD and Azure | C3: Task | D3: Done | E3: Medium | F3: Thiraphat Panthong | G3: 2026-02-11 | H3: 2026-02-11 | J3: SCRUM Sprint 2 | K3: SCRUM-58 | L3: Deploy
A4: SCRUM-324 | B4: Azure Portal Config | C4: Subtask | D4: Done | E4: Medium | F4: Thiraphat Panthong | G4: 2026-02-11 | H4: 2026-02-11 | J4: SCRUM Sprint 2 | K4: SCRUM-317 | L4: PoC with CI/CD and Azure
A5: SCRUM-323 | B5: Setup DNS record | C5: Subtask | D5: Done | E5: Medium | F5: Thiraphat Panthong | G5: 2026-02-11 | H5: 2026-02-11 | J5: SCRUM Sprint 2 | K5: SCRUM-317 | L5: PoC with CI/CD and Azure
A6: SCRUM-322 | B6: MailerSend | C6: Subtask | D6: Done | E6: Medium | F6: Thiraphat Panthong | G6: 2026-02-11 | H6: 2026-02-11 | J6: SCRUM Sprint 2 | K6: SCRUM-317 | L6: PoC with CI/CD and Azure
A7: SCRUM-321 | B7: Domain Name | C7: Subtask | D7: Done | E7: Medium | F7: Thiraphat Panthong | G7: 2026-02-11 | H7: 2026-02-11 | J7: SCRUM Sprint 2 | K7: SCRUM-317 | L7: PoC with CI/CD and Azure
A8: SCRUM-320 | B8: Setup Terraform | C8: Subtask | D8: Done | E8: Medium | F8: Thiraphat Panthong | G8: 2026-02-11 | H8: 2026-02-11 | J8: SCRUM Sprint 2 | K8: SCRUM-317 | L8: PoC with CI/CD and Azure
A9: SCRUM-319 | B9: Set Secret Key in Reposity | C9: Subtask | D9: Done | E9: Medium | F9: Thiraphat Panthong | G9: 2026-02-11 | H9: 2026-02-11 | J9: SCRUM Sprint 2 | K9: SCRUM-317 | L9: PoC with CI/CD and Azure
A10: SCRUM-318 | B10: GitHub Action to ACR | C10: Subtask | D10: Done | E10: Medium | F10: Thiraphat Panthong | G10: 2026-02-11 | H10: 2026-02-11 | J10: SCRUM Sprint 2 | K10: SCRUM-317 | L10: PoC with CI/CD and Azure
A11: SCRUM-59 | B11: Last code review | C11: Task | D11: To Do | E11: Medium | F11: Thiraphat Panthong | G11: 2025-11-19 | H11: 2026-04-10 | J11: SCRUM Sprint 4 | K11: SCRUM-58 | L11: Deploy
A12: SCRUM-304 | B12: Authentication | C12: Subtask | D12: To Do | E12: Medium | F12: Thiraphat Panthong | G12: 2026-02-07 | H12: 2026-02-18 | J12: SCRUM Sprint 4 | K12: SCRUM-59 | L12: Last code review
A13: SCRUM-303 | B13: Learning Path | C13: Subtask | D13: To Do | E13: Medium | F13: Thiraphat Panthong | G13: 2026-02-07 | H13: 2026-02-18 | J13: SCRUM Sprint 4 | K13: SCRUM-59 | L13: Last code review
A14: SCRUM-302 | B14: Reflection | C14: Subtask | D14: To Do | E14: Medium | F14: Thiraphat Panthong | G14: 2026-02-07 | H14: 2026-02-18 | J14: SCRUM Sprint 4 | K14: SCRUM-59 | L14: Last code review

Sheet _Data
A1: Sheet | B1: SCRUM Key | C1: SCRUM Number | D1: Issue Type | E1: Status
A2: Reflection Tree | B2: SCRUM-3 | C2: =IFERROR(VALUE(MID(B2,7,LEN(B2)-6)),"") -> 3 | D2: Epic | E2: Done
A3: Reflection Tree | B3: SCRUM-191 | C3: =IFERROR(VALUE(MID(B3,7,LEN(B3)-6)),"") -> 191 | D3: Task | E3: Done
A4: Reflection Tree | B4: SCRUM-13 | C4: =IFERROR(VALUE(MID(B4,7,LEN(B4)-6)),"") -> 13 | D4: Task | E4: Done
A5: Reflection Tree | B5: SCRUM-226 | C5: =IFERROR(VALUE(MID(B5,7,LEN(B5)-6)),"") -> 226 | D5: Subtask | E5: Done
A6: Reflection Tree | B6: SCRUM-225 | C6: =IFERROR(VALUE(MID(B6,7,LEN(B6)-6)),"") -> 225 | D6: Subtask | E6: Done
A7: Reflection Tree | B7: SCRUM-224 | C7: =IFERROR(VALUE(MID(B7,7,LEN(B7)-6)),"") -> 224 | D7: Subtask | E7: Done
A8: Reflection Tree | B8: SCRUM-223 | C8: =IFERROR(VALUE(MID(B8,7,LEN(B8)-6)),"") -> 223 | D8: Subtask | E8: Done
A9: Reflection Tree | B9: SCRUM-221 | C9: =IFERROR(VALUE(MID(B9,7,LEN(B9)-6)),"") -> 221 | D9: Subtask | E9: Done
A10: Reflection Tree | B10: SCRUM-220 | C10: =IFERROR(VALUE(MID(B10,7,LEN(B10)-6)),"") -> 220 | D10: Subtask | E10: Done
A11: Reflection Tree | B11: SCRUM-15 | C11: =IFERROR(VALUE(MID(B11,7,LEN(B11)-6)),"") -> 15 | D11: Task | E11: Done
A12: Reflection Tree | B12: SCRUM-230 | C12: =IFERROR(VALUE(MID(B12,7,LEN(B12)-6)),"") -> 230 | D12: Subtask | E12: Done
A13: Reflection Tree | B13: SCRUM-227 | C13: =IFERROR(VALUE(MID(B13,7,LEN(B13)-6)),"") -> 227 | D13: Subtask | E13: Done
... A255: Social Learning | B255: SCRUM-358 | C255: =IFERROR(VALUE(MID(B255,7,LEN(B255)-6)),"") -> 358 | D255: Subtask | E255: Done
A256: Deploy | B256: SCRUM-58 | C256: =IFERROR(VALUE(MID(B250,7,LEN(B250)-6)),"") -> 354 | D256: Epic | E256: In Progress
A257: Deploy | B257: SCRUM-317 | C257: =IFERROR(VALUE(MID(B251,7,LEN(B251)-6)),"") -> 355 | D257: Task | E257: Done
A258: Deploy | B258: SCRUM-324 | C258: =IFERROR(VALUE(MID(B252,7,LEN(B252)-6)),"") -> 356 | D258: Subtask | E258: Done
A259: Deploy | B259: SCRUM-323 | C259: =IFERROR(VALUE(MID(B253,7,LEN(B253)-6)),"") -> 353 | D259: Subtask | E259: Done
A260: Deploy | B260: SCRUM-322 | C260: =IFERROR(VALUE(MID(B254,7,LEN(B254)-6)),"") -> 357 | D260: Subtask | E260: Done
A261: Deploy | B261: SCRUM-321 | C261: =IFERROR(VALUE(MID(B255,7,LEN(B255)-6)),"") -> 358 | D261: Subtask | E261: Done
A262: Deploy | B262: SCRUM-320 | C262: =IFERROR(VALUE(MID(B256,7,LEN(B256)-6)),"") -> 58 | D262: Subtask | E262: Done
A263: Deploy | B263: SCRUM-319 | C263: =IFERROR(VALUE(MID(B257,7,LEN(B257)-6)),"") -> 317 | D263: Subtask | E263: Done
A264: Deploy | B264: SCRUM-318 | C264: =IFERROR(VALUE(MID(B258,7,LEN(B258)-6)),"") -> 324 | D264: Subtask | E264: Done
A265: Deploy | B265: SCRUM-59 | C265: =IFERROR(VALUE(MID(B259,7,LEN(B259)-6)),"") -> 323 | D265: Task | E265: To Do
A266: Deploy | B266: SCRUM-304 | C266: =IFERROR(VALUE(MID(B260,7,LEN(B260)-6)),"") -> 322 | D266: Subtask | E266: To Do
A267: Deploy | B267: SCRUM-303 | C267: =IFERROR(VALUE(MID(B261,7,LEN(B261)-6)),"") -> 321 | D267: Subtask | E267: To Do
... A273: Dashboards | B273: SCRUM-32 | C273: =IFERROR(VALUE(MID(B267,7,LEN(B267)-6)),"") -> 303 | D273: Task | E273: To Do

Sheet _Lists
A1: Parent Summary | B1: Reporter | C1: Assignee | D1: Sprint
A2: AI Insight Analysis | B2: Amy Tripp | C2: Amy Tripp | D2: SCRUM Sprint 1
A3: API Design | B3: Napadech | C3: Napadech | D3: SCRUM Sprint 2
A4: Admin Page | B4: Nutgritta Prasomthongsuk | C4: Nattapat Suwansipaisan | D4: SCRUM Sprint 3
A5: Authentication | B5: Thiraphat Panthong | C5: Nutgritta Prasomthongsuk | D5: SCRUM Sprint 4
A6: Authentication Pages | C6: Thiraphat Panthong
A7: Collection Learning Path
A8: Component-Widget
A9: Dashboard Layout
A10: Dashboards
A11: Data Pipeline
A12: Database Design
A13: Deploy
A14: History System
A15: Infrastructure Set
A16: Integrate system (Deploy)
A17: Landing Page
A18: Last code review
... A43: UX/UI
